Workbook

Sheet Assumptions
A1: Parameter | B1: Value | C1: Unit | D1: Source
A3: Infrastructure
A4: Number of extra stores | B4: 436 | C4: stores | D4: Assignment Assumtion (b)
A5: Number of distribution centers | B5: 10 | C5: DCs | D5: Assignment Assumtion (b)
A6: Portals per store | B6: 1 | C6: portals/store | D6: Assignment Assumtion (b)
A7: Readers per store | B7: 2 | C7: readers/store | D7: Assignment Assumtion (b)
A8: Portals per distribution center | B8: 2 | C8: portals/DC | D8: Assignment Assumtion (b)
A9: Readers per distribution center | B9: 5 | C9: readers/DC | D9: Assignment Assumtion (b)
A11: Hardware Unit Costs
A12: RFID Portal | B12: 8500 | C12: € | D12: Case p.11 - portal cost ~€8,500
A13: UHF Reader | B13: 3350 | C13: € | D13: Case footnote 23: $700-$6,000
A15: Hardware Cost Totals
A16: Total portals (stores + DCs) | B16: =B4*B6+B5*B8 -> 456 | C16: portals
A17: Total readers (stores + DCs) | B17: =B4*B7+B5*B9 -> 922 | C17: readers
A18: Total portal cost | B18: =B16*B12 -> 3876000 | C18: €
A19: Total reader cost | B19: =B17*B13 -> 3088700 | C19: €
A20: Hardware cost variance factor | B20: 1.15 | C20: % | D20: Assignment: 100-130%
A21: TOTAL HARDWARE COST | B21: =B18+B19 -> 6964700 | C21: €
A23: Software Costs
A24: Software cost multiplier | B24: 1.5 | C24: x | D24: Assignment Assumtion (c)
A25: Software cost | B25: =B21*B24 -> 10447050 | C25: €
A26: Annual maintenance (% of cost) | B26: 0.25 | C26: % | D26: Assignment Assumtion (c)
A27: Annual maintenance cost | B27: =B25*B26 -> 2611762.5 | C27: €/yr
A29: Modern Scenario
A30: Modern cost factor | B30: 0.5 | C30: x | D30: Assignment note: 50% of original
A31: Modern hardware cost | B31: =B21*B30 -> 3482350 | C31: €
A32: Modern software cost | B32: =B31*B24 -> 5223525 | C32: €
A33: Modern annual maintenance | B33: =B32*B26 -> 1305881.2 | C33: €/yr
A35: RFID Tag Costs
A36: Tag cost - HIGH scenario (historical) | B36: 0.5 | C36: €/tag | D36: Assignment Requirement
A37: Tag cost - LOW scenario (modern) | B37: 0.1 | C37: €/tag | D37: Assignment Requirement
A39: Volume Estimates (Pallet & Case Throughput)
A40: Pallets per store per week | B40: 30 | C40: pallets/store/wk | D40: Case p.7: 24-36 pallets/wk midpoint
A41: Weeks per year | B41: 52 | C41: weeks
A42: Total annual pallets | B42: =B4*B40*B41 -> 680160 | C42: pallets/yr
A43: Cases per pallet | B43: 70 | C43: cases/pallet | D43: Case p.7: 60-80 cases/pallet midpoint
A44: Total annual cases | B44: =B42*B43 -> 47611200 | C44: cases/yr
A46: Pallet-level Benefits
A47: Total retailer benefit per pallet | B47: 0.157 | C47: €/pallet | D47: Exhibit 9: 11.2+2.8+1.7 = 15.7 cents
A48: Total manufacturer benefit per pallet | B48: 0.5 | C48: €/pallet | D48: Exhibit 9: 20+5+25 = 50 cents
...

Sheet Pallet NPV (Historical)
A1: Key Inputs from Assumptions
A2: Retailer benefit per pallet | B2: =Assumptions!B47 -> 0.157 | C2: =Assumptions!C47 -> €/pallet
A3: Total annual pallets | B3: =Assumptions!B42 -> 680160 | C3: =Assumptions!C42 -> pallets/yr
A4: Productivity benefit growth rate | B4: =Assumptions!B88 -> 0.05 | C4: =Assumptions!C88 -> %/yr
A5: Historical hardware cost | B5: =Assumptions!B21 -> 6964700 | C5: =Assumptions!C21 -> €
A6: Cost variance factor | B6: =Assumptions!B20 -> 1.15 | C6: =Assumptions!C20 -> %
A7: Historical software cost | B7: =Assumptions!B25 -> 10447050 | C7: =Assumptions!C25 -> €
A8: Historical software maintenace cost | B8: =Assumptions!B27 -> 2611762.5 | C8: =Assumptions!C27 -> €/yr
A9: Historical tag cost | B9: =Assumptions!B36 -> 0.5 | C9: =Assumptions!C36 -> €/tag
A10: Depreciation life | B10: =Assumptions!B85 -> 5 | C10: =Assumptions!C85 -> years
A11: Income tax rate | B11: =Assumptions!B82 -> 0.3 | C11: =Assumptions!C82 -> %
A12: Discount rate | B12: =Assumptions!B81 -> 0.15 | C12: =Assumptions!C81 -> %
A14: Year | B14: 0 | C14: 1 | D14: 2 | E14: 3 | F14: 4 | G14: 5 | H14: 6 | I14: 7 | J14: 8 | K14: 9 | L14: 10
A15: Benefits
A16: Base annual pallet savings | B16: 0 | C16: =$B$2*$B$3 -> 106785.12 | D16: =$B$2*$B$3 -> 106785.12 | E16: =$B$2*$B$3 -> 106785.12 | F16: =$B$2*$B$3 -> 106785.12 | G16: =$B$2*$B$3 -> 106785.12 | H16: =$B$2*$B$3 -> 106785.12 | I16: =$B$2*$B$3 -> 106785.12 | J16: =$B$2*$B$3 -> 106785.12 | ... L16: =$B$2*$B$3 -> 106785.12
A17: Cumulative growth factor | B17: 1 | C17: =(1+$B$4)^C14 -> 1.05 | D17: =(1+$B$4)^D14 -> 1.1025 | E17: =(1+$B$4)^E14 -> 1.157625 | F17: =(1+$B$4)^F14 -> 1.2155063 | G17: =(1+$B$4)^G14 -> 1.2762816 | H17: =(1+$B$4)^5 -> 1.2762816 | I17: =(1+$B$4)^5 -> 1.2762816 | J17: =(1+$B$4)^5 -> 1.2762816 | K17: =(1+$B$4)^5 -> 1.2762816 | L17: =(1+$B$4)^5 -> 1.2762816
A18: Total Annual Benefit | B18: =B16*B17 -> 0 | C18: =C16*C17 -> 112124.38 | D18: =D16*D17 -> 117730.59 | E18: =E16*E17 -> 123617.12 | F18: =F16*F17 -> 129797.98 | G18: =G16*G17 -> 136287.88 | H18: =H16*H17 -> 136287.88 | I18: =I16*I17 -> 136287.88 | ... L18: =L16*L17 -> 136287.88
A20: Costs
A21: Initial capital expenditure | B21: =B5*B6+B7*B6 -> 20023512 | C21: 0 | D21: 0 | E21: 0 | F21: 0 | G21: 0 | H21: 0 | I21: 0 | J21: 0 | K21: 0 | L21: 0
A22: Annual tag cost | B22: 0 | C22: =$B$9*$B$3 -> 340080 | D22: =$B$9*$B$3 -> 340080 | E22: =$B$9*$B$3 -> 340080 | F22: =$B$9*$B$3 -> 340080 | G22: =$B$9*$B$3 -> 340080 | H22: =$B$9*$B$3 -> 340080 | I22: =$B$9*$B$3 -> 340080 | J22: =$B$9*$B$3 -> 340080 | ... L22: =$B$9*$B$3 -> 340080
A23: Annual software maintenance | B23: 0 | C23: =$B$8*$B$6 -> 3003526.9 | D23: =$B$8*$B$6 -> 3003526.9 | E23: =$B$8*$B$6 -> 3003526.9 | F23: =$B$8*$B$6 -> 3003526.9 | G23: =$B$8*$B$6 -> 3003526.9 | H23: =$B$8*$B$6 -> 3003526.9 | I23: =$B$8*$B$6 -> 3003526.9 | J23: =$B$8*$B$6 -> 3003526.9 | ... L23: =$B$8*$B$6 -> 3003526.9
A24: Total Annual Cost | B24: =B21+B22+B23 -> 20023512 | C24: =C21+C22+C23 -> 3343606.9 | D24: =D21+D22+D23 -> 3343606.9 | E24: =E21+E22+E23 -> 3343606.9 | F24: =F21+F22+F23 -> 3343606.9 | G24: =G21+G22+G23 -> 3343606.9 | H24: =H21+H22+H23 -> 3343606.9 | I24: =I21+I22+I23 -> 3343606.9 | ... L24: =L21+L22+L23 -> 3343606.9
A26: Annual Profit | B26: =B18-B24 -> -20023512 | C26: =C18-C24 -> -3231482.5 | D26: =D18-D24 -> -3225876.3 | E26: =E18-E24 -> -3219989.8 | F26: =F18-F24 -> -3213808.9 | G26: =G18-G24 -> -3207319 | H26: =H18-H24 -> -3207319 | I26: =I18-I24 -> -3207319 | ... L26: =L18-L24 -> -3207319
A28: Depreciation & Taxes
A29: Depreciation | B29: =0 -> 0 | C29: =$B$21/$B$10 -> 4004702.5 | D29: =$B$21/$B$10 -> 4004702.5 | E29: =$B$21/$B$10 -> 4004702.5 | F29: =$B$21/$B$10 -> 4004702.5 | G29: =$B$21/$B$10 -> 4004702.5 | H29: 0 | I29: 0 | J29: 0 | K29: 0 | L29: 0
A30: Profit before taxes | B30: =B26-B29 -> -20023512 | C30: =C26-C29 -> -7236185 | D30: =D26-D29 -> -7230578.8 | E30: =E26-E29 -> -7224692.3 | F30: =F26-F29 -> -7218511.4 | G30: =G26-G29 -> -7212021.5 | H30: =H26-H29 -> -3207319 | I30: =I26-I29 -> -3207319 | ... L30: =L26-L29 -> -3207319
A31: Income taxes | B31: =MAX(0, B30*$B$11) -> 0 | C31: =MAX(0, C30*$B$11) -> 0 | D31: =MAX(0, D30*$B$11) -> 0 | E31: =MAX(0, E30*$B$11) -> 0 | F31: =MAX(0, F30*$B$11) -> 0 | G31: =MAX(0, G30*$B$11) -> 0 | H31: =MAX(0, H30*$B$11) -> 0 | I31: =MAX(0, I30*$B$11) -> 0 | ... L31: =MAX(0, L30*$B$11) -> 0
A33: Net Income | B33: =B30-B31 -> -20023512 | C33: =C30-C31 -> -7236185 | D33: =D30-D31 -> -7230578.8 | E33: =E30-E31 -> -7224692.3 | F33: =F30-F31 -> -7218511.4 | G33: =G30-G31 -> -7212021.5 | H33: =H30-H31 -> -3207319 | I33: =I30-I31 -> -3207319 | ... L33: =L30-L31 -> -3207319
A35: Cash Flow
A36: Cash Flow | B36: =B29+B33 -> -20023512 | C36: =C29+C33 -> -3231482.5 | D36: =D29+D33 -> -3225876.3 | E36: =E29+E33 -> -3219989.8 | F36: =F29+F33 -> -3213808.9 | G36: =G29+G33 -> -3207319 | H36: =H29+H33 -> -3207319 | I36: =I29+I33 -> -3207319 | ... L36: =L29+L33 -> -3207319
A37: Discounted Cash Flow | B37: =B36/((1+$B$12)^B14) -> -20023512 | C37: =C36/((1+$B$12)^C14) -> -2809984.8 | D37: =D36/((1+$B$12)^D14) -> -2439225.9 | E37: =E36/((1+$B$12)^E14) -> -2117195.5 | F37: =F36/((1+$B$12)^F14) -> -1837505.7 | G37: =G36/((1+$B$12)^G14) -> -1594604.4 | H37: =H36/((1+$B$12)^H14) -> -1386612.5 | I37: =I36/((1+$B$12)^I14) -> -1205750 | ... L37: =L36/((1+$B$12)^L14) -> -792800.2
A39: NPV | B39: =NPV(B12,C36:L36)+B36 -> -36167390
A41: =B39 -> -36167390 | B41: 0.1 | C41: 0.12 | D41: 0.15 | E41: 0.2 | F41: 0.25
A42: 0.075 | B42: -40192968 | C42: -38571427 | D42: -36500045 | E42: -33789311 | F42: -31748689
A43: 0.1 | B43: -40067781 | C43: -38456691 | D43: -36398625 | E43: -33705251 | F43: -31677628
A44: 0.12 | B44: -39967632 | C44: -38364902 | D44: -36317490 | E44: -33638002 | F44: -31620779
A45: 0.157 | B45: -39782355 | C45: -38195092 | D45: -36167390 | E45: -33513594 | F45: -31515609
A46: 0.18 | B46: -39667183 | C46: -38089534 | D46: -36074084 | E46: -33436258 | F46: -31450232
A47: 0.2 | B47: -39567034 | C47: -37997745 | D47: -35992949 | E47: -33369010 | F47: -31393384
A48: 0.25 | B48: -39316660 | C48: -37768272 | D48: -35790111 | E48: -33200890 | F48: -31251262
...

Sheet Pallet NPV (Modern)
A1: Key Inputs from Assumptions
A2: Retailer benefit per pallet | B2: =Assumptions!B47 -> 0.157 | C2: =Assumptions!C47 -> €/pallet
A3: Total annual pallets | B3: =Assumptions!B42 -> 680160 | C3: =Assumptions!C42 -> pallets/yr
A4: Productivity benefit growth rate | B4: =Assumptions!B88 -> 0.05 | C4: =Assumptions!C88 -> %/yr
A5: Modern hardware cost | B5: =Assumptions!B31 -> 3482350 | C5: =Assumptions!C31 -> €
A6: Cost variance factor | B6: =Assumptions!B20 -> 1.15 | C6: =Assumptions!C20 -> %
A7: Modern software cost | B7: =Assumptions!B32 -> 5223525 | C7: =Assumptions!C32 -> €
A8: Modern software maintenance cost | B8: =Assumptions!B33 -> 1305881.2 | C8: =Assumptions!C33 -> €/yr
A9: Modern tag cost | B9: =Assumptions!B37 -> 0.1 | C9: =Assumptions!C37 -> €/tag
A10: Depreciation life | B10: =Assumptions!B85 -> 5 | C10: =Assumptions!C85 -> years
A11: Income tax rate | B11: =Assumptions!B82 -> 0.3 | C11: =Assumptions!C82 -> %
A12: Discount rate | B12: =Assumptions!B81 -> 0.15 | C12: =Assumptions!C81 -> %
A14: Year | B14: 0 | C14: 1 | D14: 2 | E14: 3 | F14: 4 | G14: 5 | H14: 6 | I14: 7 | J14: 8 | K14: 9 | L14: 10
A15: Benefits
A16: Base annual pallet savings | B16: 0 | C16: =$B$2*$B$3 -> 106785.12 | D16: =$B$2*$B$3 -> 106785.12 | E16: =$B$2*$B$3 -> 106785.12 | F16: =$B$2*$B$3 -> 106785.12 | G16: =$B$2*$B$3 -> 106785.12 | H16: =$B$2*$B$3 -> 106785.12 | I16: =$B$2*$B$3 -> 106785.12 | J16: =$B$2*$B$3 -> 106785.12 | ... L16: =$B$2*$B$3 -> 106785.12
A17: Cumulative growth factor | B17: 1 | C17: =(1+$B$4)^C14 -> 1.05 | D17: =(1+$B$4)^D14 -> 1.1025 | E17: =(1+$B$4)^E14 -> 1.157625 | F17: =(1+$B$4)^F14 -> 1.2155063 | G17: =(1+$B$4)^G14 -> 1.2762816 | H17: =(1+$B$4)^5 -> 1.2762816 | I17: =(1+$B$4)^5 -> 1.2762816 | J17: =(1+$B$4)^5 -> 1.2762816 | K17: =(1+$B$4)^5 -> 1.2762816 | L17: =(1+$B$4)^5 -> 1.2762816
A18: Total Annual Benefit | B18: =B16*B17 -> 0 | C18: =C16*C17 -> 112124.38 | D18: =D16*D17 -> 117730.59 | E18: =E16*E17 -> 123617.12 | F18: =F16*F17 -> 129797.98 | G18: =G16*G17 -> 136287.88 | H18: =H16*H17 -> 136287.88 | I18: =I16*I17 -> 136287.88 | ... L18: =L16*L17 -> 136287.88
A20: Costs
A21: Initial capital expenditure | B21: =B5*B6+B7*B6 -> 10011756 | C21: 0 | D21: 0 | E21: 0 | F21: 0 | G21: 0 | H21: 0 | I21: 0 | J21: 0 | K21: 0 | L21: 0
A22: Annual tag cost | B22: 0 | C22: =$B$9*$B$3 -> 68016 | D22: =$B$9*$B$3 -> 68016 | E22: =$B$9*$B$3 -> 68016 | F22: =$B$9*$B$3 -> 68016 | G22: =$B$9*$B$3 -> 68016 | H22: =$B$9*$B$3 -> 68016 | I22: =$B$9*$B$3 -> 68016 | J22: =$B$9*$B$3 -> 68016 | ... L22: =$B$9*$B$3 -> 68016
A23: Annual software maintenance | B23: 0 | C23: =$B$8*$B$6 -> 1501763.4 | D23: =$B$8*$B$6 -> 1501763.4 | E23: =$B$8*$B$6 -> 1501763.4 | F23: =$B$8*$B$6 -> 1501763.4 | G23: =$B$8*$B$6 -> 1501763.4 | H23: =$B$8*$B$6 -> 1501763.4 | I23: =$B$8*$B$6 -> 1501763.4 | J23: =$B$8*$B$6 -> 1501763.4 | ... L23: =$B$8*$B$6 -> 1501763.4
A24: Total Annual Cost | B24: =B21+B22+B23 -> 10011756 | C24: =C21+C22+C23 -> 1569779.4 | D24: =D21+D22+D23 -> 1569779.4 | E24: =E21+E22+E23 -> 1569779.4 | F24: =F21+F22+F23 -> 1569779.4 | G24: =G21+G22+G23 -> 1569779.4 | H24: =H21+H22+H23 -> 1569779.4 | I24: =I21+I22+I23 -> 1569779.4 | ... L24: =L21+L22+L23 -> 1569779.4
A26: Annual Profit | B26: =B18-B24 -> -10011756 | C26: =C18-C24 -> -1457655.1 | D26: =D18-D24 -> -1452048.8 | E26: =E18-E24 -> -1446162.3 | F26: =F18-F24 -> -1439981.5 | G26: =G18-G24 -> -1433491.6 | H26: =H18-H24 -> -1433491.6 | I26: =I18-I24 -> -1433491.6 | ... L26: =L18-L24 -> -1433491.6
A28: Depreciation & Taxes
A29: Depreciation | B29: =0 -> 0 | C29: =$B$21/$B$10 -> 2002351.2 | D29: =$B$21/$B$10 -> 2002351.2 | E29: =$B$21/$B$10 -> 2002351.2 | F29: =$B$21/$B$10 -> 2002351.2 | G29: =$B$21/$B$10 -> 2002351.2 | H29: 0 | I29: 0 | J29: 0 | K29: 0 | L29: 0
A30: Profit before taxes | B30: =B26-B29 -> -10011756 | C30: =C26-C29 -> -3460006.3 | D30: =D26-D29 -> -3454400.1 | E30: =E26-E29 -> -3448513.6 | F30: =F26-F29 -> -3442332.7 | G30: =G26-G29 -> -3435842.8 | H30: =H26-H29 -> -1433491.6 | I30: =I26-I29 -> -1433491.6 | ... L30: =L26-L29 -> -1433491.6
A31: Income taxes | B31: =MAX(0, B30*$B$11) -> 0 | C31: =MAX(0, C30*$B$11) -> 0 | D31: =MAX(0, D30*$B$11) -> 0 | E31: =MAX(0, E30*$B$11) -> 0 | F31: =MAX(0, F30*$B$11) -> 0 | G31: =MAX(0, G30*$B$11) -> 0 | H31: =MAX(0, H30*$B$11) -> 0 | I31: =MAX(0, I30*$B$11) -> 0 | ... L31: =MAX(0, L30*$B$11) -> 0
A33: Net Income | B33: =B30-B31 -> -10011756 | C33: =C30-C31 -> -3460006.3 | D33: =D30-D31 -> -3454400.1 | E33: =E30-E31 -> -3448513.6 | F33: =F30-F31 -> -3442332.7 | G33: =G30-G31 -> -3435842.8 | H33: =H30-H31 -> -1433491.6 | I33: =I30-I31 -> -1433491.6 | ... L33: =L30-L31 -> -1433491.6
A35: Cash Flow
A36: Cash Flow | B36: =B29+B33 -> -10011756 | C36: =C29+C33 -> -1457655.1 | D36: =D29+D33 -> -1452048.8 | E36: =E29+E33 -> -1446162.3 | F36: =F29+F33 -> -1439981.5 | G36: =G29+G33 -> -1433491.6 | H36: =H29+H33 -> -1433491.6 | I36: =I29+I33 -> -1433491.6 | ... L36: =L29+L33 -> -1433491.6
A37: Discounted Cash Flow | B37: =B36/((1+$B$12)^B14) -> -10011756 | C37: =C36/((1+$B$12)^C14) -> -1267526.1 | D37: =D36/((1+$B$12)^D14) -> -1097957.5 | E37: =E36/((1+$B$12)^E14) -> -950875.2 | F37: =F36/((1+$B$12)^F14) -> -823314.07 | G37: =G36/((1+$B$12)^G14) -> -712698.65 | H37: =H36/((1+$B$12)^H14) -> -619737.96 | I37: =I36/((1+$B$12)^I14) -> -538902.57 | ... L37: =L36/((1+$B$12)^L14) -> -354337.19
A39: NPV | B39: =NPV(B12,C36:L36)+B36 -> -17253204
A41: =B39 -> -17253204 | B41: 0.1 | C41: 0.12 | D41: 0.15 | E41: 0.2 | F41: 0.25
A42: 0.075 | B42: -19281810 | C42: -18537151 | D42: -17585859 | E42: -16340832 | F42: -15403476
A43: 0.1 | B43: -19156623 | C43: -18422414 | D43: -17484440 | E43: -16256772 | F43: -15332415
A44: 0.12 | B44: -19056474 | C44: -18330625 | D44: -17403304 | E44: -16189524 | F44: -15275566
A45: 0.157 | B45: -18871197 | C45: -18160815 | D45: -17253204 | E45: -16065115 | F45: -15170396
A46: 0.18 | B46: -18756025 | C46: -18055257 | D46: -17159899 | E46: -15987780 | F46: -15105020
A47: 0.2 | B47: -18655876 | C47: -17963468 | D47: -17078763 | E47: -15920532 | F47: -15048171
A48: 0.25 | B48: -18405502 | C48: -17733995 | D48: -16875925 | E48: -15752412 | F48: -14906049
...

Sheet Case NPV (Historical)
A1: Key Inputs from Assumptions
A2: Total retailer benefit per case | B2: =Assumptions!B57 -> 0.089 | C2: =Assumptions!C57 -> €/case
A3: Productivity benefit ratio | B3: =Assumptions!B52 -> 0.26966292 | C3: =Assumptions!C52 -> %
A4: Stockout benefit ratio | B4: =Assumptions!B54 -> 0.56179775 | C4: =Assumptions!C54 -> %
A5: Mispicked reduction benefit ratio | B5: =Assumptions!B56 -> 0.16853933 | C5: =Assumptions!C56 -> %
A6: Total annual cases | B6: =Assumptions!B44 -> 47611200 | C6: =Assumptions!C44 -> cases/yr
A7: Productivity benefit growth rate | B7: =Assumptions!B88 -> 0.05 | C7: =Assumptions!C88 -> %/yr
A8: Year 1 shrink savings | B8: =Assumptions!B65 -> 12500000 | C8: =Assumptions!C65 -> €/yr
A9: Shrink reduction additional improvement | B9: =Assumptions!B89 -> 0.05 | C9: %/yr
A10: Historical hardware cost | B10: =Assumptions!B21 -> 6964700 | C10: =Assumptions!C21 -> €
A11: Cost variance factor | B11: =Assumptions!B20 -> 1.15 | C11: =Assumptions!C20 -> %
A12: Historical software cost | B12: =Assumptions!B25 -> 10447050 | C12: =Assumptions!C25 -> €
A13: Historical software maintenace cost | B13: =Assumptions!B27 -> 2611762.5 | C13: =Assumptions!C27 -> €/yr
A14: Historical tag cost | B14: =Assumptions!B36 -> 0.5 | C14: =Assumptions!C36 -> €/tag
A15: Depreciation life | B15: =Assumptions!B85 -> 5 | C15: =Assumptions!C85 -> years
A16: Income tax rate | B16: =Assumptions!B82 -> 0.3 | C16: =Assumptions!C82 -> %
A17: Discount rate | B17: =Assumptions!B81 -> 0.15 | C17: =Assumptions!C81 -> %
A19: Year | B19: 0 | C19: 1 | D19: 2 | E19: 3 | F19: 4 | G19: 5 | H19: 6 | I19: 7 | J19: 8 | K19: 9 | L19: 10
A20: Benefits
A21: Base annual productivity case savings | B21: 0 | C21: =$B$2*$B$3*$B$6 -> 1142668.8 | D21: =$B$2*$B$3*$B$6 -> 1142668.8 | E21: =$B$2*$B$3*$B$6 -> 1142668.8 | F21: =$B$2*$B$3*$B$6 -> 1142668.8 | G21: =$B$2*$B$3*$B$6 -> 1142668.8 | H21: =$B$2*$B$3*$B$6 -> 1142668.8 | I21: =$B$2*$B$3*$B$6 -> 1142668.8 | J21: =$B$2*$B$3*$B$6 -> 1142668.8 | ... L21: =$B$2*$B$3*$B$6 -> 1142668.8
A22: Cumulative productivity growth factor | B22: 1 | C22: =(1+$B$7)^C19 -> 1.05 | D22: =(1+$B$7)^D19 -> 1.1025 | E22: =(1+$B$7)^E19 -> 1.157625 | F22: =(1+$B$7)^F19 -> 1.2155063 | G22: =(1+$B$7)^G19 -> 1.2762816 | H22: =(1+$B$7)^5 -> 1.2762816 | I22: =(1+$B$7)^5 -> 1.2762816 | J22: =(1+$B$7)^5 -> 1.2762816 | K22: =(1+$B$7)^5 -> 1.2762816 | L22: =(1+$B$7)^5 -> 1.2762816
A23: Annual non-productivity case savings | B23: 0 | C23: =$B$5*$B$2*$B$6 -> 714168 | D23: =$B$5*$B$2*$B$6 -> 714168 | E23: =$B$5*$B$2*$B$6 -> 714168 | F23: =$B$5*$B$2*$B$6 -> 714168 | G23: =$B$5*$B$2*$B$6 -> 714168 | H23: =$B$5*$B$2*$B$6 -> 714168 | I23: =$B$5*$B$2*$B$6 -> 714168 | J23: =$B$5*$B$2*$B$6 -> 714168 | ... L23: =$B$5*$B$2*$B$6 -> 714168
A24: Base annual shrink savings | B24: 0 | C24: =$B$8 -> 12500000 | D24: =$B$8 -> 12500000 | E24: =$B$8 -> 12500000 | F24: =$B$8 -> 12500000 | G24: =$B$8 -> 12500000 | H24: =$B$8 -> 12500000 | I24: =$B$8 -> 12500000 | J24: =$B$8 -> 12500000 | ... L24: =$B$8 -> 12500000
A25: Cumulative shrink growth factor | B25: 1 | C25: =(1+$B$9)^C19 -> 1.05 | D25: =(1+$B$9)^D19 -> 1.1025 | E25: =(1+$B$9)^E19 -> 1.157625 | F25: =(1+$B$9)^F19 -> 1.2155063 | G25: =(1+$B$9)^G19 -> 1.2762816 | H25: =(1+$B$9)^5 -> 1.2762816 | I25: =(1+$B$9)^5 -> 1.2762816 | J25: =(1+$B$9)^5 -> 1.2762816 | K25: =(1+$B$9)^5 -> 1.2762816 | L25: =(1+$B$9)^5 -> 1.2762816
A26: Total Annual Benefit | B26: =B21*B22 -> 0 | C26: =C21*C22+C23+C24*C25 -> 15038970 | D26: =D21*D22+D23+D24*D25 -> 15755210 | E26: =E21*E22+E23+E24*E25 -> 16507262 | F26: =F21*F22+F23+F24*F25 -> 17296917 | G26: =G21*G22+G23+G24*G25 -> 18126055 | H26: =H21*H22+H23+H24*H25 -> 18126055 | I26: =I21*I22+I23+I24*I25 -> 18126055 | J26: =J21*J22+J23+J24*J25 -> 18126055 | ... L26: =L21*L22+L23+L24*L25 -> 18126055
A28: Costs
A29: Initial capital expenditure | B29: =B10*B11+B12*B11 -> 20023512 | C29: 0 | D29: 0 | E29: 0 | F29: 0 | G29: 0 | H29: 0 | I29: 0 | J29: 0 | K29: 0 | L29: 0
A30: Annual tag cost | B30: 0 | C30: =$B$14*$B$6 -> 23805600 | D30: =$B$14*$B$6 -> 23805600 | E30: =$B$14*$B$6 -> 23805600 | F30: =$B$14*$B$6 -> 23805600 | G30: =$B$14*$B$6 -> 23805600 | H30: =$B$14*$B$6 -> 23805600 | I30: =$B$14*$B$6 -> 23805600 | J30: =$B$14*$B$6 -> 23805600 | ... L30: =$B$14*$B$6 -> 23805600
A31: Annual software maintenance | B31: 0 | C31: =$B$13*$B$11 -> 3003526.9 | D31: =$B$13*$B$11 -> 3003526.9 | E31: =$B$13*$B$11 -> 3003526.9 | F31: =$B$13*$B$11 -> 3003526.9 | G31: =$B$13*$B$11 -> 3003526.9 | H31: =$B$13*$B$11 -> 3003526.9 | I31: =$B$13*$B$11 -> 3003526.9 | J31: =$B$13*$B$11 -> 3003526.9 | ... L31: =$B$13*$B$11 -> 3003526.9
A32: Total Annual Cost | B32: =B29+B30+B31 -> 20023512 | C32: =C29+C30+C31 -> 26809127 | D32: =D29+D30+D31 -> 26809127 | E32: =E29+E30+E31 -> 26809127 | F32: =F29+F30+F31 -> 26809127 | G32: =G29+G30+G31 -> 26809127 | H32: =H29+H30+H31 -> 26809127 | I32: =I29+I30+I31 -> 26809127 | ... L32: =L29+L30+L31 -> 26809127
A34: Annual Profit | B34: =B26-B32 -> -20023512 | C34: =C26-C32 -> -11770157 | D34: =D26-D32 -> -11053917 | E34: =E26-E32 -> -10301864 | F34: =F26-F32 -> -9512209.7 | G34: =G26-G32 -> -8683072.2 | H34: =H26-H32 -> -8683072.2 | I34: =I26-I32 -> -8683072.2 | ... L34: =L26-L32 -> -8683072.2
A36: Depreciation & Taxes
A37: Depreciation | B37: =0 -> 0 | C37: =$B$29/$B$15 -> 4004702.5 | D37: =$B$29/$B$15 -> 4004702.5 | E37: =$B$29/$B$15 -> 4004702.5 | F37: =$B$29/$B$15 -> 4004702.5 | G37: =$B$29/$B$15 -> 4004702.5 | H37: 0 | I37: 0 | J37: 0 | K37: 0 | L37: 0
A38: Profit before taxes | B38: =B34-B37 -> -20023512 | C38: =C34-C37 -> -15774859 | D38: =D34-D37 -> -15058619 | E38: =E34-E37 -> -14306567 | F38: =F34-F37 -> -13516912 | G38: =G34-G37 -> -12687775 | H38: =H34-H37 -> -8683072.2 | I38: =I34-I37 -> -8683072.2 | ... L38: =L34-L37 -> -8683072.2
A39: Income taxes | B39: =MAX(0, B38*$B$16) -> 0 | C39: =MAX(0, C38*$B$16) -> 0 | D39: =MAX(0, D38*$B$16) -> 0 | E39: =MAX(0, E38*$B$16) -> 0 | F39: =MAX(0, F38*$B$16) -> 0 | G39: =MAX(0, G38*$B$16) -> 0 | H39: =MAX(0, H38*$B$16) -> 0 | I39: =MAX(0, I38*$B$16) -> 0 | ... L39: =MAX(0, L38*$B$16) -> 0
A41: Net Income | B41: =B38-B39 -> -20023512 | C41: =C38-C39 -> -15774859 | D41: =D38-D39 -> -15058619 | E41: =E38-E39 -> -14306567 | F41: =F38-F39 -> -13516912 | G41: =G38-G39 -> -12687775 | H41: =H38-H39 -> -8683072.2 | I41: =I38-I39 -> -8683072.2 | ... L41: =L38-L39 -> -8683072.2
A43: Cash Flow
A44: Cash Flow | B44: =B37+B41 -> -20023512 | C44: =C37+C41 -> -11770157 | D44: =D37+D41 -> -11053917 | E44: =E37+E41 -> -10301864 | F44: =F37+F41 -> -9512209.7 | G44: =G37+G41 -> -8683072.2 | H44: =H37+H41 -> -8683072.2 | I44: =I37+I41 -> -8683072.2 | ... L44: =L37+L41 -> -8683072.2
A45: Discounted Cash Flow | B45: =B44/((1+$B$17)^B19) -> -20023512 | C45: =C44/((1+$B$17)^C19) -> -10234919 | D45: =D44/((1+$B$17)^D19) -> -8358349 | E45: =E44/((1+$B$17)^E19) -> -6773643.1 | F45: =F44/((1+$B$17)^F19) -> -5438636.8 | G45: =G44/((1+$B$17)^G19) -> -4317021.5 | H45: =H44/((1+$B$17)^H19) -> -3753931.7 | I45: =I44/((1+$B$17)^I19) -> -3264288.5 | ... L45: =L44/((1+$B$17)^L19) -> -2146322.7
A47: NPV | B47: =NPV(B17,C44:L44)+B44 -> -69617407
...

Sheet Case NPV (Modern)
A1: Key Inputs from Assumptions
A2: Total retailer benefit per case | B2: =Assumptions!B57 -> 0.089 | C2: =Assumptions!C57 -> €/case
A3: Productivity benefit ratio | B3: =Assumptions!B52 -> 0.26966292 | C3: =Assumptions!C52 -> %
A4: Stockout benefit ratio | B4: =Assumptions!B54 -> 0.56179775 | C4: =Assumptions!C54 -> %
A5: Mispicked reduction benefit ratio | B5: =Assumptions!B56 -> 0.16853933 | C5: =Assumptions!C56 -> %
A6: Total annual cases | B6: =Assumptions!B44 -> 47611200 | C6: =Assumptions!C44 -> cases/yr
A7: Productivity benefit growth rate | B7: =Assumptions!B88 -> 0.05 | C7: =Assumptions!C88 -> %/yr
A8: Year 1 shrink savings | B8: =Assumptions!B65 -> 12500000 | C8: =Assumptions!C65 -> €/yr
A9: Shrink reduction additional improvement | B9: =Assumptions!B89 -> 0.05 | C9: %/yr
A10: Modern hardware cost | B10: =Assumptions!B31 -> 3482350 | C10: =Assumptions!C31 -> €
A11: Cost variance factor | B11: =Assumptions!B20 -> 1.15 | C11: =Assumptions!C20 -> %
A12: Modern software cost | B12: =Assumptions!B32 -> 5223525 | C12: =Assumptions!C32 -> €
A13: Modern software maintenance cost | B13: =Assumptions!B33 -> 1305881.2 | C13: =Assumptions!C33 -> €/yr
A14: Modern tag cost | B14: =Assumptions!B37 -> 0.1 | C14: =Assumptions!C37 -> €/tag
A15: Depreciation life | B15: =Assumptions!B85 -> 5 | C15: =Assumptions!C85 -> years
A16: Income tax rate | B16: =Assumptions!B82 -> 0.3 | C16: =Assumptions!C82 -> %
A17: Discount rate | B17: =Assumptions!B81 -> 0.15 | C17: =Assumptions!C81 -> %
A19: Year | B19: 0 | C19: 1 | D19: 2 | E19: 3 | F19: 4 | G19: 5 | H19: 6 | I19: 7 | J19: 8 | K19: 9 | L19: 10
A20: Benefits
A21: Base annual productivity case savings | B21: 0 | C21: =$B$2*$B$3*$B$6 -> 1142668.8 | D21: =$B$2*$B$3*$B$6 -> 1142668.8 | E21: =$B$2*$B$3*$B$6 -> 1142668.8 | F21: =$B$2*$B$3*$B$6 -> 1142668.8 | G21: =$B$2*$B$3*$B$6 -> 1142668.8 | H21: =$B$2*$B$3*$B$6 -> 1142668.8 | I21: =$B$2*$B$3*$B$6 -> 1142668.8 | J21: =$B$2*$B$3*$B$6 -> 1142668.8 | ... L21: =$B$2*$B$3*$B$6 -> 1142668.8
A22: Cumulative productivity growth factor | B22: 1 | C22: =(1+$B$7)^C19 -> 1.05 | D22: =(1+$B$7)^D19 -> 1.1025 | E22: =(1+$B$7)^E19 -> 1.157625 | F22: =(1+$B$7)^F19 -> 1.2155063 | G22: =(1+$B$7)^G19 -> 1.2762816 | H22: =(1+$B$7)^5 -> 1.2762816 | I22: =(1+$B$7)^5 -> 1.2762816 | J22: =(1+$B$7)^5 -> 1.2762816 | K22: =(1+$B$7)^5 -> 1.2762816 | L22: =(1+$B$7)^5 -> 1.2762816
A23: Annual non-productivity case savings | B23: 0 | C23: =$B$5*$B$2*$B$6 -> 714168 | D23: =$B$5*$B$2*$B$6 -> 714168 | E23: =$B$5*$B$2*$B$6 -> 714168 | F23: =$B$5*$B$2*$B$6 -> 714168 | G23: =$B$5*$B$2*$B$6 -> 714168 | H23: =$B$5*$B$2*$B$6 -> 714168 | I23: =$B$5*$B$2*$B$6 -> 714168 | J23: =$B$5*$B$2*$B$6 -> 714168 | ... L23: =$B$5*$B$2*$B$6 -> 714168
A24: Base annual shrink savings | B24: 0 | C24: =$B$8 -> 12500000 | D24: =$B$8 -> 12500000 | E24: =$B$8 -> 12500000 | F24: =$B$8 -> 12500000 | G24: =$B$8 -> 12500000 | H24: =$B$8 -> 12500000 | I24: =$B$8 -> 12500000 | J24: =$B$8 -> 12500000 | ... L24: =$B$8 -> 12500000
A25: Cumulative shrink growth factor | B25: 1 | C25: =(1+$B$9)^C19 -> 1.05 | D25: =(1+$B$9)^D19 -> 1.1025 | E25: =(1+$B$9)^E19 -> 1.157625 | F25: =(1+$B$9)^F19 -> 1.2155063 | G25: =(1+$B$9)^G19 -> 1.2762816 | H25: =(1+$B$9)^5 -> 1.2762816 | I25: =(1+$B$9)^5 -> 1.2762816 | J25: =(1+$B$9)^5 -> 1.2762816 | K25: =(1+$B$9)^5 -> 1.2762816 | L25: =(1+$B$9)^5 -> 1.2762816
A26: Total Annual Benefit | B26: =B21*B22 -> 0 | C26: =C21*C22+C23+C24*C25 -> 15038970 | D26: =D21*D22+D23+D24*D25 -> 15755210 | E26: =E21*E22+E23+E24*E25 -> 16507262 | F26: =F21*F22+F23+F24*F25 -> 17296917 | G26: =G21*G22+G23+G24*G25 -> 18126055 | H26: =H21*H22+H23+H24*H25 -> 18126055 | I26: =I21*I22+I23+I24*I25 -> 18126055 | J26: =J21*J22+J23+J24*J25 -> 18126055 | ... L26: =L21*L22+L23+L24*L25 -> 18126055
A28: Costs
A29: Initial capital expenditure | B29: =B10*B11+B12*B11 -> 10011756 | C29: 0 | D29: 0 | E29: 0 | F29: 0 | G29: 0 | H29: 0 | I29: 0 | J29: 0 | K29: 0 | L29: 0
A30: Annual tag cost | B30: 0 | C30: =$B$14*$B$6 -> 4761120 | D30: =$B$14*$B$6 -> 4761120 | E30: =$B$14*$B$6 -> 4761120 | F30: =$B$14*$B$6 -> 4761120 | G30: =$B$14*$B$6 -> 4761120 | H30: =$B$14*$B$6 -> 4761120 | I30: =$B$14*$B$6 -> 4761120 | J30: =$B$14*$B$6 -> 4761120 | ... L30: =$B$14*$B$6 -> 4761120
A31: Annual software maintenance | B31: 0 | C31: =$B$13*$B$11 -> 1501763.4 | D31: =$B$13*$B$11 -> 1501763.4 | E31: =$B$13*$B$11 -> 1501763.4 | F31: =$B$13*$B$11 -> 1501763.4 | G31: =$B$13*$B$11 -> 1501763.4 | H31: =$B$13*$B$11 -> 1501763.4 | I31: =$B$13*$B$11 -> 1501763.4 | J31: =$B$13*$B$11 -> 1501763.4 | ... L31: =$B$13*$B$11 -> 1501763.4
A32: Total Annual Cost | B32: =B29+B30+B31 -> 10011756 | C32: =C29+C30+C31 -> 6262883.4 | D32: =D29+D30+D31 -> 6262883.4 | E32: =E29+E30+E31 -> 6262883.4 | F32: =F29+F30+F31 -> 6262883.4 | G32: =G29+G30+G31 -> 6262883.4 | H32: =H29+H30+H31 -> 6262883.4 | I32: =I29+I30+I31 -> 6262883.4 | ... L32: =L29+L30+L31 -> 6262883.4
A34: Annual Profit | B34: =B26-B32 -> -10011756 | C34: =C26-C32 -> 8776086.8 | D34: =D26-D32 -> 9492326.9 | E34: =E26-E32 -> 10244379 | F34: =F26-F32 -> 11034034 | G34: =G26-G32 -> 11863171 | H34: =H26-H32 -> 11863171 | I34: =I26-I32 -> 11863171 | ... L34: =L26-L32 -> 11863171
A36: Depreciation & Taxes
A37: Depreciation | B37: =0 -> 0 | C37: =$B$29/$B$15 -> 2002351.2 | D37: =$B$29/$B$15 -> 2002351.2 | E37: =$B$29/$B$15 -> 2002351.2 | F37: =$B$29/$B$15 -> 2002351.2 | G37: =$B$29/$B$15 -> 2002351.2 | H37: 0 | I37: 0 | J37: 0 | K37: 0 | L37: 0
A38: Profit before taxes | B38: =B34-B37 -> -10011756 | C38: =C34-C37 -> 6773735.6 | D38: =D34-D37 -> 7489975.7 | E38: =E34-E37 -> 8242027.8 | F38: =F34-F37 -> 9031682.5 | G38: =G34-G37 -> 9860820 | H38: =H34-H37 -> 11863171 | I38: =I34-I37 -> 11863171 | ... L38: =L34-L37 -> 11863171
A39: Income taxes | B39: =MAX(0, B38*$B$16) -> 0 | C39: =MAX(0, C38*$B$16) -> 2032120.7 | D39: =MAX(0, D38*$B$16) -> 2246992.7 | E39: =MAX(0, E38*$B$16) -> 2472608.3 | F39: =MAX(0, F38*$B$16) -> 2709504.8 | G39: =MAX(0, G38*$B$16) -> 2958246 | H39: =MAX(0, H38*$B$16) -> 3558951.4 | I39: =MAX(0, I38*$B$16) -> 3558951.4 | ... L39: =MAX(0, L38*$B$16) -> 3558951.4
A41: Net Income | B41: =B38-B39 -> -10011756 | C41: =C38-C39 -> 4741614.9 | D41: =D38-D39 -> 5242983 | E41: =E38-E39 -> 5769419.4 | F41: =F38-F39 -> 6322177.8 | G41: =G38-G39 -> 6902574 | H41: =H38-H39 -> 8304219.9 | I41: =I38-I39 -> 8304219.9 | ... L41: =L38-L39 -> 8304219.9
A43: Cash Flow
A44: Cash Flow | B44: =B37+B41 -> -10011756 | C44: =C37+C41 -> 6743966.1 | D44: =D37+D41 -> 7245334.2 | E44: =E37+E41 -> 7771770.7 | F44: =F37+F41 -> 8324529 | G44: =G37+G41 -> 8904925.2 | H44: =H37+H41 -> 8304219.9 | I44: =I37+I41 -> 8304219.9 | ... L44: =L37+L41 -> 8304219.9
A45: Discounted Cash Flow | B45: =B44/((1+$B$17)^B19) -> -10011756 | C45: =C44/((1+$B$17)^C19) -> 5864318.4 | D45: =D44/((1+$B$17)^D19) -> 5478513.6 | E45: =E44/((1+$B$17)^E19) -> 5110065.4 | F45: =F44/((1+$B$17)^F19) -> 4759576.5 | G45: =G44/((1+$B$17)^G19) -> 4427321.7 | H45: =H44/((1+$B$17)^H19) -> 3590143.4 | I45: =I44/((1+$B$17)^I19) -> 3121863.8 | ... L45: =L44/((1+$B$17)^L19) -> 2052676.1
A47: NPV | B47: =NPV(B17,C44:L44)+B44 -> 29467964
...

Sheet Case NPV (Historical + AI)
A1: Key Inputs from Assumptions
A2: Total retailer benefit per case | B2: =Assumptions!B57 -> 0.089 | C2: =Assumptions!C57 -> €/case
A3: Productivity benefit ratio | B3: =Assumptions!B52 -> 0.26966292 | C3: =Assumptions!C52 -> %
A4: Stockout benefit ratio | B4: =Assumptions!B54 -> 0.56179775 | C4: =Assumptions!C54 -> %
A5: Mispicked reduction benefit ratio | B5: =Assumptions!B56 -> 0.16853933 | C5: =Assumptions!C56 -> %
A6: Total annual cases | B6: =Assumptions!B44 -> 47611200 | C6: =Assumptions!C44 -> cases/yr
A7: Productivity benefit growth rate | B7: =Assumptions!B88 -> 0.05 | C7: =Assumptions!C88 -> %/yr
A8: Stockout benefit growth rate | B8: =Assumptions!B90 -> 0.05 | C8: =Assumptions!C90 -> %/yr
A9: Year 1 shrink savings | B9: =Assumptions!B65 -> 12500000 | C9: =Assumptions!C65 -> €/yr
A10: Shrink reduction additional improvement | B10: =Assumptions!B89 -> 0.05 | C10: %/yr
A11: Annual inventory savings | B11: =Assumptions!B72 -> 3750000 | C11: =Assumptions!C72 -> €/yr
A12: Historical hardware cost | B12: =Assumptions!B21 -> 6964700 | C12: =Assumptions!C21 -> €
A13: Cost variance factor | B13: =Assumptions!B20 -> 1.15 | C13: =Assumptions!C20 -> %
A14: Historical software cost | B14: =Assumptions!B25 -> 10447050 | C14: =Assumptions!C25 -> €
A15: Historical software maintenace cost | B15: =Assumptions!B27 -> 2611762.5 | C15: =Assumptions!C27 -> €/yr
A16: Historical tag cost | B16: =Assumptions!B36 -> 0.5 | C16: =Assumptions!C36 -> €/tag
A17: Initial AI cost | B17: =Assumptions!B76 -> 65400000 | C17: =Assumptions!C76 -> €
A18: Annual AI cost | B18: =Assumptions!B78 -> 32700000 | C18: =Assumptions!C78 -> €/yr
A19: Depreciation life | B19: =Assumptions!B85 -> 5 | C19: =Assumptions!C85 -> years
A20: Income tax rate | B20: =Assumptions!B82 -> 0.3 | C20: =Assumptions!C82 -> %
A21: Discount rate | B21: =Assumptions!B81 -> 0.15 | C21: =Assumptions!C81 -> %
A23: Year | B23: 0 | C23: 1 | D23: 2 | E23: 3 | F23: 4 | G23: 5 | H23: 6 | I23: 7 | J23: 8 | K23: 9 | L23: 10
A24: Benefits
A25: Base annual productivity case savings | B25: 0 | C25: =$B$2*$B$3*$B$6 -> 1142668.8 | D25: =$B$2*$B$3*$B$6 -> 1142668.8 | E25: =$B$2*$B$3*$B$6 -> 1142668.8 | F25: =$B$2*$B$3*$B$6 -> 1142668.8 | G25: =$B$2*$B$3*$B$6 -> 1142668.8 | H25: =$B$2*$B$3*$B$6 -> 1142668.8 | I25: =$B$2*$B$3*$B$6 -> 1142668.8 | J25: =$B$2*$B$3*$B$6 -> 1142668.8 | ... L25: =$B$2*$B$3*$B$6 -> 1142668.8
A26: Cumulative productivity growth factor | B26: 1 | C26: =(1+$B$7)^C23 -> 1.05 | D26: =(1+$B$7)^D23 -> 1.1025 | E26: =(1+$B$7)^E23 -> 1.157625 | F26: =(1+$B$7)^F23 -> 1.2155063 | G26: =(1+$B$7)^G23 -> 1.2762816 | H26: =(1+$B$7)^5 -> 1.2762816 | I26: =(1+$B$7)^5 -> 1.2762816 | J26: =(1+$B$7)^5 -> 1.2762816 | K26: =(1+$B$7)^5 -> 1.2762816 | L26: =(1+$B$7)^5 -> 1.2762816
A27: Base annual stockout case savings | B27: 0 | C27: =$B$4*$B$2*$B$6 -> 2380560 | D27: =$B$4*$B$2*$B$6 -> 2380560 | E27: =$B$4*$B$2*$B$6 -> 2380560 | F27: =$B$4*$B$2*$B$6 -> 2380560 | G27: =$B$4*$B$2*$B$6 -> 2380560 | H27: =$B$4*$B$2*$B$6 -> 2380560 | I27: =$B$4*$B$2*$B$6 -> 2380560 | J27: =$B$4*$B$2*$B$6 -> 2380560 | ... L27: =$B$4*$B$2*$B$6 -> 2380560
A28: Cumulative stockout growth factor | B28: 1 | C28: =(1+$B$8)^C23 -> 1.05 | D28: =(1+$B$8)^D23 -> 1.1025 | E28: =(1+$B$8)^E23 -> 1.157625 | F28: =(1+$B$8)^F23 -> 1.2155063 | G28: =(1+$B$8)^G23 -> 1.2762816 | H28: =(1+$B$8)^5 -> 1.2762816 | I28: =(1+$B$8)^5 -> 1.2762816 | J28: =(1+$B$8)^5 -> 1.2762816 | K28: =(1+$B$8)^5 -> 1.2762816 | L28: =(1+$B$8)^5 -> 1.2762816
A29: Annual mispicked savings | B29: 0 | C29: =$B$5*$B$2*$B$6 -> 714168 | D29: =$B$5*$B$2*$B$6 -> 714168 | E29: =$B$5*$B$2*$B$6 -> 714168 | F29: =$B$5*$B$2*$B$6 -> 714168 | G29: =$B$5*$B$2*$B$6 -> 714168 | H29: =$B$5*$B$2*$B$6 -> 714168 | I29: =$B$5*$B$2*$B$6 -> 714168 | J29: =$B$5*$B$2*$B$6 -> 714168 | ... L29: =$B$5*$B$2*$B$6 -> 714168
A30: Base annual shrink savings | B30: 0 | C30: =$B$9 -> 12500000 | D30: =$B$9 -> 12500000 | E30: =$B$9 -> 12500000 | F30: =$B$9 -> 12500000 | G30: =$B$9 -> 12500000 | H30: =$B$9 -> 12500000 | I30: =$B$9 -> 12500000 | J30: =$B$9 -> 12500000 | ... L30: =$B$9 -> 12500000
A31: Cumulative shrink growth factor | B31: 1 | C31: =(1+$B$10)^C23 -> 1.05 | D31: =(1+$B$10)^D23 -> 1.1025 | E31: =(1+$B$10)^E23 -> 1.157625 | F31: =(1+$B$10)^F23 -> 1.2155063 | G31: =(1+$B$10)^G23 -> 1.2762816 | H31: =(1+$B$10)^5 -> 1.2762816 | I31: =(1+$B$10)^5 -> 1.2762816 | J31: =(1+$B$10)^5 -> 1.2762816 | K31: =(1+$B$10)^5 -> 1.2762816 | L31: =(1+$B$10)^5 -> 1.2762816
A32: Annual inventory savings | B32: 0 | C32: =$B$11 -> 3750000 | D32: =$B$11 -> 3750000 | E32: =$B$11 -> 3750000 | F32: =$B$11 -> 3750000 | G32: =$B$11 -> 3750000 | H32: =$B$11 -> 3750000 | I32: =$B$11 -> 3750000 | J32: =$B$11 -> 3750000 | ... L32: =$B$11 -> 3750000
A33: Total Annual Benefit | B33: =B25*B26 -> 0 | C33: =C25*C26+C27*C28+C29+C30*C31+C32 -> 21288558 | D33: =D25*D26+D27*D28+D29+D30*D31+D32 -> 22129778 | E33: =E25*E26+E27*E28+E29+E30*E31+E32 -> 23013058 | F33: =F25*F26+F27*F28+F29+F30*F31+F32 -> 23940503 | G33: =G25*G26+G27*G28+G29+G30*G31+G32 -> 24914319 | H33: =H25*H26+H27*H28+H29+H30*H31+H32 -> 24914319 | I33: =I25*I26+I27*I28+I29+I30*I31+I32 -> 24914319 | J33: =J25*J26+J27*J28+J29+J30*J31+J32 -> 24914319 | ... L33: =L25*L26+L27*L28+L29+L30*L31+L32 -> 24914319
A35: Costs
A36: Initial capital expenditure | B36: =B12*B13+B14*B13+B17 -> 85423512 | C36: 0 | D36: 0 | E36: 0 | F36: 0 | G36: 0 | H36: 0 | I36: 0 | J36: 0 | K36: 0 | L36: 0
A37: Annual tag cost | B37: 0 | C37: =$B$16*$B$6 -> 23805600 | D37: =$B$16*$B$6 -> 23805600 | E37: =$B$16*$B$6 -> 23805600 | F37: =$B$16*$B$6 -> 23805600 | G37: =$B$16*$B$6 -> 23805600 | H37: =$B$16*$B$6 -> 23805600 | I37: =$B$16*$B$6 -> 23805600 | J37: =$B$16*$B$6 -> 23805600 | ... L37: =$B$16*$B$6 -> 23805600
A38: Annual software maintenance | B38: 0 | C38: =$B$15*$B$13 -> 3003526.9 | D38: =$B$15*$B$13 -> 3003526.9 | E38: =$B$15*$B$13 -> 3003526.9 | F38: =$B$15*$B$13 -> 3003526.9 | G38: =$B$15*$B$13 -> 3003526.9 | H38: =$B$15*$B$13 -> 3003526.9 | I38: =$B$15*$B$13 -> 3003526.9 | J38: =$B$15*$B$13 -> 3003526.9 | ... L38: =$B$15*$B$13 -> 3003526.9
A39: Annual AI cost | B39: 0 | C39: =$B$18 -> 32700000 | D39: =$B$18 -> 32700000 | E39: =$B$18 -> 32700000 | F39: =$B$18 -> 32700000 | G39: =$B$18 -> 32700000 | H39: =$B$18 -> 32700000 | I39: =$B$18 -> 32700000 | J39: =$B$18 -> 32700000 | ... L39: =$B$18 -> 32700000
A40: Total Annual Cost | B40: =B36+B37+B38 -> 85423512 | C40: =C36+C37+C38+C39 -> 59509127 | D40: =D36+D37+D38+D39 -> 59509127 | E40: =E36+E37+E38+E39 -> 59509127 | F40: =F36+F37+F38+F39 -> 59509127 | G40: =G36+G37+G38+G39 -> 59509127 | H40: =H36+H37+H38+H39 -> 59509127 | I40: =I36+I37+I38+I39 -> 59509127 | J40: =J36+J37+J38+J39 -> 59509127 | ... L40: =L36+L37+L38+L39 -> 59509127
A42: Annual Profit | B42: =B33-B40 -> -85423512 | C42: =C33-C40 -> -38220569 | D42: =D33-D40 -> -37379349 | E42: =E33-E40 -> -36496069 | F42: =F33-F40 -> -35568624 | G42: =G33-G40 -> -34594807 | H42: =H33-H40 -> -34594807 | I42: =I33-I40 -> -34594807 | ... L42: =L33-L40 -> -34594807
A44: Depreciation & Taxes
...

Sheet Case NPV (Modern + AI)
A1: Key Inputs from Assumptions
A2: Total retailer benefit per case | B2: =Assumptions!B57 -> 0.089 | C2: =Assumptions!C57 -> €/case
A3: Productivity benefit ratio | B3: =Assumptions!B52 -> 0.26966292 | C3: =Assumptions!C52 -> %
A4: Stockout benefit ratio | B4: =Assumptions!B54 -> 0.56179775 | C4: =Assumptions!C54 -> %
A5: Mispicked reduction benefit ratio | B5: =Assumptions!B56 -> 0.16853933 | C5: =Assumptions!C56 -> %
A6: Total annual cases | B6: =Assumptions!B44 -> 47611200 | C6: =Assumptions!C44 -> cases/yr
A7: Productivity benefit growth rate | B7: =Assumptions!B88 -> 0.05 | C7: =Assumptions!C88 -> %/yr
A8: Stockout benefit growth rate | B8: =Assumptions!B90 -> 0.05 | C8: =Assumptions!C90 -> %/yr
A9: Year 1 shrink savings | B9: =Assumptions!B65 -> 12500000 | C9: =Assumptions!C65 -> €/yr
A10: Shrink reduction additional improvement | B10: =Assumptions!B89 -> 0.05 | C10: %/yr
A11: Annual inventory savings | B11: =Assumptions!B72 -> 3750000 | C11: =Assumptions!C72 -> €/yr
A12: Modern hardware cost | B12: =Assumptions!B31 -> 3482350 | C12: =Assumptions!C31 -> €
A13: Cost variance factor | B13: =Assumptions!B20 -> 1.15 | C13: =Assumptions!C20 -> %
A14: Modern software cost | B14: =Assumptions!B32 -> 5223525 | C14: =Assumptions!C32 -> €
A15: Modern software maintenance cost | B15: =Assumptions!B33 -> 1305881.2 | C15: =Assumptions!C33 -> €/yr
A16: Modern tag cost | B16: =Assumptions!B37 -> 0.1 | C16: =Assumptions!C37 -> €/tag
A17: Initial AI cost | B17: =Assumptions!B76 -> 65400000 | C17: =Assumptions!C76 -> €
A18: Annual AI cost | B18: =Assumptions!B78 -> 32700000 | C18: =Assumptions!C78 -> €/yr
A19: Depreciation life | B19: =Assumptions!B85 -> 5 | C19: =Assumptions!C85 -> years
A20: Income tax rate | B20: =Assumptions!B82 -> 0.3 | C20: =Assumptions!C82 -> %
A21: Discount rate | B21: =Assumptions!B81 -> 0.15 | C21: =Assumptions!C81 -> %
A23: Year | B23: 0 | C23: 1 | D23: 2 | E23: 3 | F23: 4 | G23: 5 | H23: 6 | I23: 7 | J23: 8 | K23: 9 | L23: 10
A24: Benefits
A25: Base annual productivity case savings | B25: 0 | C25: =$B$2*$B$3*$B$6 -> 1142668.8 | D25: =$B$2*$B$3*$B$6 -> 1142668.8 | E25: =$B$2*$B$3*$B$6 -> 1142668.8 | F25: =$B$2*$B$3*$B$6 -> 1142668.8 | G25: =$B$2*$B$3*$B$6 -> 1142668.8 | H25: =$B$2*$B$3*$B$6 -> 1142668.8 | I25: =$B$2*$B$3*$B$6 -> 1142668.8 | J25: =$B$2*$B$3*$B$6 -> 1142668.8 | ... L25: =$B$2*$B$3*$B$6 -> 1142668.8
A26: Cumulative productivity growth factor | B26: 1 | C26: =(1+$B$7)^C23 -> 1.05 | D26: =(1+$B$7)^D23 -> 1.1025 | E26: =(1+$B$7)^E23 -> 1.157625 | F26: =(1+$B$7)^F23 -> 1.2155063 | G26: =(1+$B$7)^G23 -> 1.2762816 | H26: =(1+$B$7)^5 -> 1.2762816 | I26: =(1+$B$7)^5 -> 1.2762816 | J26: =(1+$B$7)^5 -> 1.2762816 | K26: =(1+$B$7)^5 -> 1.2762816 | L26: =(1+$B$7)^5 -> 1.2762816
A27: Base annual stockout case savings | B27: 0 | C27: =$B$4*$B$2*$B$6 -> 2380560 | D27: =$B$4*$B$2*$B$6 -> 2380560 | E27: =$B$4*$B$2*$B$6 -> 2380560 | F27: =$B$4*$B$2*$B$6 -> 2380560 | G27: =$B$4*$B$2*$B$6 -> 2380560 | H27: =$B$4*$B$2*$B$6 -> 2380560 | I27: =$B$4*$B$2*$B$6 -> 2380560 | J27: =$B$4*$B$2*$B$6 -> 2380560 | ... L27: =$B$4*$B$2*$B$6 -> 2380560
A28: Cumulative stockout growth factor | B28: 1 | C28: =(1+$B$8)^C23 -> 1.05 | D28: =(1+$B$8)^D23 -> 1.1025 | E28: =(1+$B$8)^E23 -> 1.157625 | F28: =(1+$B$8)^F23 -> 1.2155063 | G28: =(1+$B$8)^G23 -> 1.2762816 | H28: =(1+$B$8)^5 -> 1.2762816 | I28: =(1+$B$8)^5 -> 1.2762816 | J28: =(1+$B$8)^5 -> 1.2762816 | K28: =(1+$B$8)^5 -> 1.2762816 | L28: =(1+$B$8)^5 -> 1.2762816
A29: Annual mispicked savings | B29: 0 | C29: =$B$5*$B$2*$B$6 -> 714168 | D29: =$B$5*$B$2*$B$6 -> 714168 | E29: =$B$5*$B$2*$B$6 -> 714168 | F29: =$B$5*$B$2*$B$6 -> 714168 | G29: =$B$5*$B$2*$B$6 -> 714168 | H29: =$B$5*$B$2*$B$6 -> 714168 | I29: =$B$5*$B$2*$B$6 -> 714168 | J29: =$B$5*$B$2*$B$6 -> 714168 | ... L29: =$B$5*$B$2*$B$6 -> 714168
A30: Base annual shrink savings | B30: 0 | C30: =$B$9 -> 12500000 | D30: =$B$9 -> 12500000 | E30: =$B$9 -> 12500000 | F30: =$B$9 -> 12500000 | G30: =$B$9 -> 12500000 | H30: =$B$9 -> 12500000 | I30: =$B$9 -> 12500000 | J30: =$B$9 -> 12500000 | ... L30: =$B$9 -> 12500000
A31: Cumulative shrink growth factor | B31: 1 | C31: =(1+$B$10)^C23 -> 1.05 | D31: =(1+$B$10)^D23 -> 1.1025 | E31: =(1+$B$10)^E23 -> 1.157625 | F31: =(1+$B$10)^F23 -> 1.2155063 | G31: =(1+$B$10)^G23 -> 1.2762816 | H31: =(1+$B$10)^5 -> 1.2762816 | I31: =(1+$B$10)^5 -> 1.2762816 | J31: =(1+$B$10)^5 -> 1.2762816 | K31: =(1+$B$10)^5 -> 1.2762816 | L31: =(1+$B$10)^5 -> 1.2762816
A32: Annual inventory savings | B32: 0 | C32: =$B$11 -> 3750000 | D32: =$B$11 -> 3750000 | E32: =$B$11 -> 3750000 | F32: =$B$11 -> 3750000 | G32: =$B$11 -> 3750000 | H32: =$B$11 -> 3750000 | I32: =$B$11 -> 3750000 | J32: =$B$11 -> 3750000 | ... L32: =$B$11 -> 3750000
A33: Total Annual Benefit | B33: =B25*B26 -> 0 | C33: =C25*C26+C27*C28+C29+C30*C31+C32 -> 21288558 | D33: =D25*D26+D27*D28+D29+D30*D31+D32 -> 22129778 | E33: =E25*E26+E27*E28+E29+E30*E31+E32 -> 23013058 | F33: =F25*F26+F27*F28+F29+F30*F31+F32 -> 23940503 | G33: =G25*G26+G27*G28+G29+G30*G31+G32 -> 24914319 | H33: =H25*H26+H27*H28+H29+H30*H31+H32 -> 24914319 | I33: =I25*I26+I27*I28+I29+I30*I31+I32 -> 24914319 | J33: =J25*J26+J27*J28+J29+J30*J31+J32 -> 24914319 | ... L33: =L25*L26+L27*L28+L29+L30*L31+L32 -> 24914319
A35: Costs
A36: Initial capital expenditure | B36: =B12*B13+B14*B13+B17 -> 75411756 | C36: 0 | D36: 0 | E36: 0 | F36: 0 | G36: 0 | H36: 0 | I36: 0 | J36: 0 | K36: 0 | L36: 0
A37: Annual tag cost | B37: 0 | C37: =$B$16*$B$6 -> 4761120 | D37: =$B$16*$B$6 -> 4761120 | E37: =$B$16*$B$6 -> 4761120 | F37: =$B$16*$B$6 -> 4761120 | G37: =$B$16*$B$6 -> 4761120 | H37: =$B$16*$B$6 -> 4761120 | I37: =$B$16*$B$6 -> 4761120 | J37: =$B$16*$B$6 -> 4761120 | ... L37: =$B$16*$B$6 -> 4761120
A38: Annual software maintenance | B38: 0 | C38: =$B$15*$B$13 -> 1501763.4 | D38: =$B$15*$B$13 -> 1501763.4 | E38: =$B$15*$B$13 -> 1501763.4 | F38: =$B$15*$B$13 -> 1501763.4 | G38: =$B$15*$B$13 -> 1501763.4 | H38: =$B$15*$B$13 -> 1501763.4 | I38: =$B$15*$B$13 -> 1501763.4 | J38: =$B$15*$B$13 -> 1501763.4 | ... L38: =$B$15*$B$13 -> 1501763.4
A39: Annual AI cost | B39: 0 | C39: =$B$18 -> 32700000 | D39: =$B$18 -> 32700000 | E39: =$B$18 -> 32700000 | F39: =$B$18 -> 32700000 | G39: =$B$18 -> 32700000 | H39: =$B$18 -> 32700000 | I39: =$B$18 -> 32700000 | J39: =$B$18 -> 32700000 | ... L39: =$B$18 -> 32700000
A40: Total Annual Cost | B40: =B36+B37+B38+B39 -> 75411756 | C40: =C36+C37+C38+C39 -> 38962883 | D40: =D36+D37+D38+D39 -> 38962883 | E40: =E36+E37+E38+E39 -> 38962883 | F40: =F36+F37+F38+F39 -> 38962883 | G40: =G36+G37+G38+G39 -> 38962883 | H40: =H36+H37+H38+H39 -> 38962883 | I40: =I36+I37+I38+I39 -> 38962883 | ... L40: =L36+L37+L38+L39 -> 38962883
A42: Annual Profit | B42: =B33-B40 -> -75411756 | C42: =C33-C40 -> -17674325 | D42: =D33-D40 -> -16833106 | E42: =E33-E40 -> -15949825 | F42: =F33-F40 -> -15022381 | G42: =G33-G40 -> -14048564 | H42: =H33-H40 -> -14048564 | I42: =I33-I40 -> -14048564 | ... L42: =L33-L40 -> -14048564
A44: Depreciation & Taxes
...
